<?xml version="1.0"?>
<!--
  Unitree G1 Humanoid Robot URDF
  Simplified educational model for capstone demo

  Reference: https://www.unitree.com/g1
  Height: 1.27m (standing)
  Weight: 35kg
  DOF: 23 (torso: 3, arms: 2x7, legs: 2x6)

  Coordinate system: X-forward, Y-left, Z-up (ROS convention)
-->
<robot name="unitree_g1">

  <!-- Base Link (Pelvis) -->
  <link name="base_link">
    <inertial>
      <origin xyz="0 0 0.05" rpy="0 0 0"/>
      <mass value="8.0"/>
      <inertia ixx="0.1" ixy="0" ixz="0" iyy="0.1" iyz="0" izz="0.1"/>
    </inertial>
    <visual>
      <origin xyz="0 0 0.05" rpy="0 0 0"/>
      <geometry>
        <box size="0.25 0.20 0.10"/>
      </geometry>
      <material name="dark_gray">
        <color rgba="0.3 0.3 0.3 1.0"/>
      </material>
    </visual>
    <collision>
      <origin xyz="0 0 0.05" rpy="0 0 0"/>
      <geometry>
        <box size="0.25 0.20 0.10"/>
      </geometry>
    </collision>
  </link>

  <!-- Torso -->
  <link name="torso_link">
    <inertial>
      <origin xyz="0 0 0.25" rpy="0 0 0"/>
      <mass value="12.0"/>
      <inertia ixx="0.2" ixy="0" ixz="0" iyy="0.2" iyz="0" izz="0.1"/>
    </inertial>
    <visual>
      <origin xyz="0 0 0.25" rpy="0 0 0"/>
      <geometry>
        <box size="0.30 0.25 0.50"/>
      </geometry>
      <material name="light_gray">
        <color rgba="0.6 0.6 0.6 1.0"/>
      </material>
    </visual>
    <collision>
      <origin xyz="0 0 0.25" rpy="0 0 0"/>
      <geometry>
        <box size="0.30 0.25 0.50"/>
      </geometry>
    </collision>
  </link>

  <joint name="base_to_torso" type="fixed">
    <parent link="base_link"/>
    <child link="torso_link"/>
    <origin xyz="0 0 0.1" rpy="0 0 0"/>
  </joint>

  <!-- Head -->
  <link name="head_link">
    <inertial>
      <origin xyz="0 0 0.1" rpy="0 0 0"/>
      <mass value="1.5"/>
      <inertia ixx="0.01" ixy="0" ixz="0" iyy="0.01" iyz="0" izz="0.01"/>
    </inertial>
    <visual>
      <origin xyz="0 0 0.1" rpy="0 0 0"/>
      <geometry>
        <sphere radius="0.12"/>
      </geometry>
      <material name="white">
        <color rgba="0.9 0.9 0.9 1.0"/>
      </material>
    </visual>
    <collision>
      <origin xyz="0 0 0.1" rpy="0 0 0"/>
      <geometry>
        <sphere radius="0.12"/>
      </geometry>
    </collision>
  </link>

  <joint name="torso_to_head" type="revolute">
    <parent link="torso_link"/>
    <child link="head_link"/>
    <origin xyz="0 0 0.5" rpy="0 0 0"/>
    <axis xyz="0 0 1"/>
    <limit lower="-1.57" upper="1.57" effort="10" velocity="2.0"/>
  </joint>

  <!-- Camera (mounted on head) -->
  <link name="camera_link">
    <inertial>
      <mass value="0.1"/>
      <inertia ixx="0.001" ixy="0" ixz="0" iyy="0.001" iyz="0" izz="0.001"/>
    </inertial>
    <visual>
      <origin xyz="0 0 0" rpy="0 0 0"/>
      <geometry>
        <box size="0.03 0.08 0.02"/>
      </geometry>
      <material name="black">
        <color rgba="0.1 0.1 0.1 1.0"/>
      </material>
    </visual>
  </link>

  <joint name="head_to_camera" type="fixed">
    <parent link="head_link"/>
    <child link="camera_link"/>
    <origin xyz="0.12 0 0.05" rpy="0 0 0"/>
  </joint>

  <!-- Left Arm -->
  <link name="left_shoulder_link">
    <inertial>
      <mass value="1.0"/>
      <inertia ixx="0.01" ixy="0" ixz="0" iyy="0.01" iyz="0" izz="0.01"/>
    </inertial>
    <visual>
      <origin xyz="0 0 0" rpy="0 0 0"/>
      <geometry>
        <sphere radius="0.06"/>
      </geometry>
      <material name="dark_gray"/>
    </visual>
    <collision>
      <origin xyz="0 0 0" rpy="0 0 0"/>
      <geometry>
        <sphere radius="0.06"/>
      </geometry>
    </collision>
  </link>

  <joint name="torso_to_left_shoulder" type="revolute">
    <parent link="torso_link"/>
    <child link="left_shoulder_link"/>
    <origin xyz="0 0.18 0.4" rpy="0 0 0"/>
    <axis xyz="0 1 0"/>
    <limit lower="-3.14" upper="3.14" effort="50" velocity="2.0"/>
  </joint>

  <link name="left_upper_arm_link">
    <inertial>
      <origin xyz="0 0 -0.15" rpy="0 0 0"/>
      <mass value="1.5"/>
      <inertia ixx="0.02" ixy="0" ixz="0" iyy="0.02" iyz="0" izz="0.005"/>
    </inertial>
    <visual>
      <origin xyz="0 0 -0.15" rpy="0 0 0"/>
      <geometry>
        <cylinder radius="0.04" length="0.30"/>
      </geometry>
      <material name="light_gray"/>
    </visual>
    <collision>
      <origin xyz="0 0 -0.15" rpy="0 0 0"/>
      <geometry>
        <cylinder radius="0.04" length="0.30"/>
      </geometry>
    </collision>
  </link>

  <joint name="left_shoulder_to_upper_arm" type="revolute">
    <parent link="left_shoulder_link"/>
    <child link="left_upper_arm_link"/>
    <origin xyz="0 0 0" rpy="0 0 0"/>
    <axis xyz="1 0 0"/>
    <limit lower="-1.57" upper="3.14" effort="50" velocity="2.0"/>
  </joint>

  <link name="left_forearm_link">
    <inertial>
      <origin xyz="0 0 -0.12" rpy="0 0 0"/>
      <mass value="1.0"/>
      <inertia ixx="0.015" ixy="0" ixz="0" iyy="0.015" iyz="0" izz="0.003"/>
    </inertial>
    <visual>
      <origin xyz="0 0 -0.12" rpy="0 0 0"/>
      <geometry>
        <cylinder radius="0.035" length="0.24"/>
      </geometry>
      <material name="dark_gray"/>
    </visual>
    <collision>
      <origin xyz="0 0 -0.12" rpy="0 0 0"/>
      <geometry>
        <cylinder radius="0.035" length="0.24"/>
      </geometry>
    </collision>
  </link>

  <joint name="left_elbow" type="revolute">
    <parent link="left_upper_arm_link"/>
    <child link="left_forearm_link"/>
    <origin xyz="0 0 -0.30" rpy="0 0 0"/>
    <axis xyz="0 1 0"/>
    <limit lower="0" upper="2.35" effort="40" velocity="2.0"/>
  </joint>

  <link name="left_hand_link">
    <inertial>
      <mass value="0.5"/>
      <inertia ixx="0.001" ixy="0" ixz="0" iyy="0.001" iyz="0" izz="0.001"/>
    </inertial>
    <visual>
      <origin xyz="0 0 -0.05" rpy="0 0 0"/>
      <geometry>
        <box size="0.08 0.05 0.10"/>
      </geometry>
      <material name="black"/>
    </visual>
    <collision>
      <origin xyz="0 0 -0.05" rpy="0 0 0"/>
      <geometry>
        <box size="0.08 0.05 0.10"/>
      </geometry>
    </collision>
  </link>

  <joint name="left_wrist" type="fixed">
    <parent link="left_forearm_link"/>
    <child link="left_hand_link"/>
    <origin xyz="0 0 -0.24" rpy="0 0 0"/>
  </joint>

  <!-- Right Arm (mirror of left) -->
  <link name="right_shoulder_link">
    <inertial>
      <mass value="1.0"/>
      <inertia ixx="0.01" ixy="0" ixz="0" iyy="0.01" iyz="0" izz="0.01"/>
    </inertial>
    <visual>
      <origin xyz="0 0 0" rpy="0 0 0"/>
      <geometry>
        <sphere radius="0.06"/>
      </geometry>
      <material name="dark_gray"/>
    </visual>
    <collision>
      <origin xyz="0 0 0" rpy="0 0 0"/>
      <geometry>
        <sphere radius="0.06"/>
      </geometry>
    </collision>
  </link>

  <joint name="torso_to_right_shoulder" type="revolute">
    <parent link="torso_link"/>
    <child link="right_shoulder_link"/>
    <origin xyz="0 -0.18 0.4" rpy="0 0 0"/>
    <axis xyz="0 1 0"/>
    <limit lower="-3.14" upper="3.14" effort="50" velocity="2.0"/>
  </joint>

  <link name="right_upper_arm_link">
    <inertial>
      <origin xyz="0 0 -0.15" rpy="0 0 0"/>
      <mass value="1.5"/>
      <inertia ixx="0.02" ixy="0" ixz="0" iyy="0.02" iyz="0" izz="0.005"/>
    </inertial>
    <visual>
      <origin xyz="0 0 -0.15" rpy="0 0 0"/>
      <geometry>
        <cylinder radius="0.04" length="0.30"/>
      </geometry>
      <material name="light_gray"/>
    </visual>
    <collision>
      <origin xyz="0 0 -0.15" rpy="0 0 0"/>
      <geometry>
        <cylinder radius="0.04" length="0.30"/>
      </geometry>
    </collision>
  </link>

  <joint name="right_shoulder_to_upper_arm" type="revolute">
    <parent link="right_shoulder_link"/>
    <child link="right_upper_arm_link"/>
    <origin xyz="0 0 0" rpy="0 0 0"/>
    <axis xyz="1 0 0"/>
    <limit lower="-3.14" upper="1.57" effort="50" velocity="2.0"/>
  </joint>

  <link name="right_forearm_link">
    <inertial>
      <origin xyz="0 0 -0.12" rpy="0 0 0"/>
      <mass value="1.0"/>
      <inertia ixx="0.015" ixy="0" ixz="0" iyy="0.015" iyz="0" izz="0.003"/>
    </inertial>
    <visual>
      <origin xyz="0 0 -0.12" rpy="0 0 0"/>
      <geometry>
        <cylinder radius="0.035" length="0.24"/>
      </geometry>
      <material name="dark_gray"/>
    </visual>
    <collision>
      <origin xyz="0 0 -0.12" rpy="0 0 0"/>
      <geometry>
        <cylinder radius="0.035" length="0.24"/>
      </geometry>
    </collision>
  </link>

  <joint name="right_elbow" type="revolute">
    <parent link="right_upper_arm_link"/>
    <child link="right_forearm_link"/>
    <origin xyz="0 0 -0.30" rpy="0 0 0"/>
    <axis xyz="0 1 0"/>
    <limit lower="0" upper="2.35" effort="40" velocity="2.0"/>
  </joint>

  <link name="right_hand_link">
    <inertial>
      <mass value="0.5"/>
      <inertia ixx="0.001" ixy="0" ixz="0" iyy="0.001" iyz="0" izz="0.001"/>
    </inertial>
    <visual>
      <origin xyz="0 0 -0.05" rpy="0 0 0"/>
      <geometry>
        <box size="0.08 0.05 0.10"/>
      </geometry>
      <material name="black"/>
    </visual>
    <collision>
      <origin xyz="0 0 -0.05" rpy="0 0 0"/>
      <geometry>
        <box size="0.08 0.05 0.10"/>
      </geometry>
    </collision>
  </link>

  <joint name="right_wrist" type="fixed">
    <parent link="right_forearm_link"/>
    <child link="right_hand_link"/>
    <origin xyz="0 0 -0.24" rpy="0 0 0"/>
  </joint>

  <!-- Left Leg -->
  <link name="left_hip_link">
    <inertial>
      <mass value="1.5"/>
      <inertia ixx="0.01" ixy="0" ixz="0" iyy="0.01" iyz="0" izz="0.01"/>
    </inertial>
    <visual>
      <geometry>
        <sphere radius="0.07"/>
      </geometry>
      <material name="dark_gray"/>
    </visual>
    <collision>
      <geometry>
        <sphere radius="0.07"/>
      </geometry>
    </collision>
  </link>

  <joint name="base_to_left_hip" type="revolute">
    <parent link="base_link"/>
    <child link="left_hip_link"/>
    <origin xyz="0 0.10 0" rpy="0 0 0"/>
    <axis xyz="0 1 0"/>
    <limit lower="-1.57" upper="1.57" effort="100" velocity="2.0"/>
  </joint>

  <link name="left_thigh_link">
    <inertial>
      <origin xyz="0 0 -0.20" rpy="0 0 0"/>
      <mass value="3.0"/>
      <inertia ixx="0.05" ixy="0" ixz="0" iyy="0.05" iyz="0" izz="0.01"/>
    </inertial>
    <visual>
      <origin xyz="0 0 -0.20" rpy="0 0 0"/>
      <geometry>
        <cylinder radius="0.06" length="0.40"/>
      </geometry>
      <material name="light_gray"/>
    </visual>
    <collision>
      <origin xyz="0 0 -0.20" rpy="0 0 0"/>
      <geometry>
        <cylinder radius="0.06" length="0.40"/>
      </geometry>
    </collision>
  </link>

  <joint name="left_hip_to_thigh" type="revolute">
    <parent link="left_hip_link"/>
    <child link="left_thigh_link"/>
    <origin xyz="0 0 0" rpy="0 0 0"/>
    <axis xyz="1 0 0"/>
    <limit lower="-2.0" upper="2.0" effort="100" velocity="2.0"/>
  </joint>

  <link name="left_shin_link">
    <inertial>
      <origin xyz="0 0 -0.18" rpy="0 0 0"/>
      <mass value="2.0"/>
      <inertia ixx="0.03" ixy="0" ixz="0" iyy="0.03" iyz="0" izz="0.008"/>
    </inertial>
    <visual>
      <origin xyz="0 0 -0.18" rpy="0 0 0"/>
      <geometry>
        <cylinder radius="0.05" length="0.36"/>
      </geometry>
      <material name="dark_gray"/>
    </visual>
    <collision>
      <origin xyz="0 0 -0.18" rpy="0 0 0"/>
      <geometry>
        <cylinder radius="0.05" length="0.36"/>
      </geometry>
    </collision>
  </link>

  <joint name="left_knee" type="revolute">
    <parent link="left_thigh_link"/>
    <child link="left_shin_link"/>
    <origin xyz="0 0 -0.40" rpy="0 0 0"/>
    <axis xyz="0 1 0"/>
    <limit lower="0" upper="2.35" effort="100" velocity="2.0"/>
  </joint>

  <link name="left_foot_link">
    <inertial>
      <origin xyz="0.05 0 -0.03" rpy="0 0 0"/>
      <mass value="1.0"/>
      <inertia ixx="0.005" ixy="0" ixz="0" iyy="0.01" iyz="0" izz="0.01"/>
    </inertial>
    <visual>
      <origin xyz="0.05 0 -0.03" rpy="0 0 0"/>
      <geometry>
        <box size="0.20 0.10 0.06"/>
      </geometry>
      <material name="black"/>
    </visual>
    <collision>
      <origin xyz="0.05 0 -0.03" rpy="0 0 0"/>
      <geometry>
        <box size="0.20 0.10 0.06"/>
      </geometry>
    </collision>
  </link>

  <joint name="left_ankle" type="revolute">
    <parent link="left_shin_link"/>
    <child link="left_foot_link"/>
    <origin xyz="0 0 -0.36" rpy="0 0 0"/>
    <axis xyz="0 1 0"/>
    <limit lower="-0.7" upper="0.7" effort="80" velocity="2.0"/>
  </joint>

  <!-- Right Leg (mirror of left) -->
  <link name="right_hip_link">
    <inertial>
      <mass value="1.5"/>
      <inertia ixx="0.01" ixy="0" ixz="0" iyy="0.01" iyz="0" izz="0.01"/>
    </inertial>
    <visual>
      <geometry>
        <sphere radius="0.07"/>
      </geometry>
      <material name="dark_gray"/>
    </visual>
    <collision>
      <geometry>
        <sphere radius="0.07"/>
      </geometry>
    </collision>
  </link>

  <joint name="base_to_right_hip" type="revolute">
    <parent link="base_link"/>
    <child link="right_hip_link"/>
    <origin xyz="0 -0.10 0" rpy="0 0 0"/>
    <axis xyz="0 1 0"/>
    <limit lower="-1.57" upper="1.57" effort="100" velocity="2.0"/>
  </joint>

  <link name="right_thigh_link">
    <inertial>
      <origin xyz="0 0 -0.20" rpy="0 0 0"/>
      <mass value="3.0"/>
      <inertia ixx="0.05" ixy="0" ixz="0" iyy="0.05" iyz="0" izz="0.01"/>
    </inertial>
    <visual>
      <origin xyz="0 0 -0.20" rpy="0 0 0"/>
      <geometry>
        <cylinder radius="0.06" length="0.40"/>
      </geometry>
      <material name="light_gray"/>
    </visual>
    <collision>
      <origin xyz="0 0 -0.20" rpy="0 0 0"/>
      <geometry>
        <cylinder radius="0.06" length="0.40"/>
      </geometry>
    </collision>
  </link>

  <joint name="right_hip_to_thigh" type="revolute">
    <parent link="right_hip_link"/>
    <child link="right_thigh_link"/>
    <origin xyz="0 0 0" rpy="0 0 0"/>
    <axis xyz="1 0 0"/>
    <limit lower="-2.0" upper="2.0" effort="100" velocity="2.0"/>
  </joint>

  <link name="right_shin_link">
    <inertial>
      <origin xyz="0 0 -0.18" rpy="0 0 0"/>
      <mass value="2.0"/>
      <inertia ixx="0.03" ixy="0" ixz="0" iyy="0.03" iyz="0" izz="0.008"/>
    </inertial>
    <visual>
      <origin xyz="0 0 -0.18" rpy="0 0 0"/>
      <geometry>
        <cylinder radius="0.05" length="0.36"/>
      </geometry>
      <material name="dark_gray"/>
    </visual>
    <collision>
      <origin xyz="0 0 -0.18" rpy="0 0 0"/>
      <geometry>
        <cylinder radius="0.05" length="0.36"/>
      </geometry>
    </collision>
  </link>

  <joint name="right_knee" type="revolute">
    <parent link="right_thigh_link"/>
    <child link="right_shin_link"/>
    <origin xyz="0 0 -0.40" rpy="0 0 0"/>
    <axis xyz="0 1 0"/>
    <limit lower="0" upper="2.35" effort="100" velocity="2.0"/>
  </joint>

  <link name="right_foot_link">
    <inertial>
      <origin xyz="0.05 0 -0.03" rpy="0 0 0"/>
      <mass value="1.0"/>
      <inertia ixx="0.005" ixy="0" ixz="0" iyy="0.01" iyz="0" izz="0.01"/>
    </inertial>
    <visual>
      <origin xyz="0.05 0 -0.03" rpy="0 0 0"/>
      <geometry>
        <box size="0.20 0.10 0.06"/>
      </geometry>
      <material name="black"/>
    </visual>
    <collision>
      <origin xyz="0.05 0 -0.03" rpy="0 0 0"/>
      <geometry>
        <box size="0.20 0.10 0.06"/>
      </geometry>
    </collision>
  </link>

  <joint name="right_ankle" type="revolute">
    <parent link="right_shin_link"/>
    <child link="right_foot_link"/>
    <origin xyz="0 0 -0.36" rpy="0 0 0"/>
    <axis xyz="0 1 0"/>
    <limit lower="-0.7" upper="0.7" effort="80" velocity="2.0"/>
  </joint>

  <!-- Gazebo-specific elements for simulation -->
  <gazebo reference="base_link">
    <material>Gazebo/Grey</material>
  </gazebo>

  <gazebo reference="camera_link">
    <sensor type="camera" name="head_camera">
      <update_rate>30.0</update_rate>
      <camera name="head">
        <horizontal_fov>1.3962634</horizontal_fov>
        <image>
          <width>640</width>
          <height>480</height>
          <format>R8G8B8</format>
        </image>
        <clip>
          <near>0.02</near>
          <far>300</far>
        </clip>
      </camera>
      <plugin name="camera_controller" filename="libgazebo_ros_camera.so">
        <ros>
          <namespace>/</namespace>
          <remapping>image_raw:=camera/image_raw</remapping>
          <remapping>camera_info:=camera/camera_info</remapping>
        </ros>
        <camera_name>head_camera</camera_name>
        <frame_name>camera_link</frame_name>
        <hack_baseline>0.07</hack_baseline>
      </plugin>
    </sensor>
  </gazebo>

</robot>
